<?xml version="1.0" ?>
<!-- =================================================================================== -->
<!-- |    This document was autogenerated by xacro from bot_world.urdf.xacro           | -->
<!-- |    EDITING THIS FILE BY HAND IS NOT RECOMMENDED                                 | -->
<!-- =================================================================================== -->
<robot name="aruco_markers">
  <link name="base_box">
    <visual>
      <origin rpy="0 0 1.57" xyz="0 0 0.0825"/>
      <geometry>
        <box size="0.255 0.21 0.165"/>
      </geometry>
      <material name="Almond">
        <color rgba="0.7 0.5 0.3 1.0"/>
      </material>
    </visual>
    <collision>
      <origin rpy="0 0 0" xyz="0 0 0.0825"/>
      <geometry>
        <box size="0.255 0.21 0.165"/>
      </geometry>
    </collision>
    <inertial>
      <origin rpy="0 0 0" xyz="0 0 0.0825"/>
      <mass value="0.180"/>
      <inertia ixx="6.0e-4" ixy="0" ixz="0" iyy="6.0e-4" iyz="0" izz="6.0e-4"/>
    </inertial>
  </link>
  <!-- <xacro:box_world name="box_1" parent="base_box"> -->
  <!-- 	<origin xyz="0.42 0 0" rpy="0 0 1.57"/> -->
  <!-- </xacro:box_world> -->
  <link name="box_2">
    <visual>
      <origin rpy="0 0 0" xyz="0 0 0.0825"/>
      <geometry>
        <box size="0.255 0.21 0.165"/>
      </geometry>
      <material name="Almond">
        <color rgba="0.7 0.5 0.3 1.0"/>
      </material>
    </visual>
    <collision>
      <origin rpy="0 0 0" xyz="0 0 0.0825"/>
      <geometry>
        <box size="0.255 0.21 0.165"/>
      </geometry>
    </collision>
    <inertial>
      <origin rpy="0 0 0" xyz="0 0 0.0825"/>
      <mass value="0.180"/>
      <inertia ixx="6.0e-4" ixy="0" ixz="0" iyy="6.0e-4" iyz="0" izz="6.0e-4"/>
    </inertial>
  </link>
  <joint name="box_2_joint" type="continuous">
    <origin rpy="0 0 1.57" xyz="-0.42 0 0"/>
    <parent link="base_box"/>
    <child link="box_2"/>
  </joint>
  <!-- <xacro:box_world name="box_3" parent="base_box"> -->
  <!-- 	<origin xyz="-0.21 -0.1275 0" rpy="0 0 1.57"/> -->
  <!-- </xacro:box_world> -->
  <link name="box_4">
    <visual>
      <origin rpy="0 0 0" xyz="0 0 0.0825"/>
      <geometry>
        <box size="0.255 0.21 0.165"/>
      </geometry>
      <material name="Almond">
        <color rgba="0.7 0.5 0.3 1.0"/>
      </material>
    </visual>
    <collision>
      <origin rpy="0 0 0" xyz="0 0 0.0825"/>
      <geometry>
        <box size="0.255 0.21 0.165"/>
      </geometry>
    </collision>
    <inertial>
      <origin rpy="0 0 0" xyz="0 0 0.0825"/>
      <mass value="0.180"/>
      <inertia ixx="6.0e-4" ixy="0" ixz="0" iyy="6.0e-4" iyz="0" izz="6.0e-4"/>
    </inertial>
  </link>
  <joint name="box_4_joint" type="continuous">
    <origin rpy="0 0 1.57" xyz="-0.63 0 0"/>
    <parent link="base_box"/>
    <child link="box_4"/>
  </joint>
  <link name="wall_1">
    <visual>
      <origin rpy="0 0 0" xyz="0 0 1.0"/>
      <geometry>
        <box size="0.2 7.5 2.0"/>
      </geometry>
      <material name="Maroon">
        <color rgba="0.5 0.0 0.0 1.0"/>
      </material>
    </visual>
    <collision>
      <origin rpy="0 0 0" xyz="0 0 1.0"/>
      <geometry>
        <box size="0.2 7.5 2.0"/>
      </geometry>
    </collision>
    <inertial>
      <origin rpy="0 0 0" xyz="0 0 1.0"/>
      <mass value="2"/>
      <inertia ixx="6.0e-2" ixy="0" ixz="0" iyy="6.0e-4" iyz="0" izz="6.0e-2"/>
    </inertial>
  </link>
  <joint name="wall_1_joint" type="continuous">
    <origin rpy="0 0 0" xyz="3.3 -1.0 0.0"/>
    <parent link="base_box"/>
    <child link="wall_1"/>
  </joint>
  <link name="wall_2">
    <visual>
      <origin rpy="0 0 0" xyz="0 0 1.0"/>
      <geometry>
        <box size="0.2 7.5 2.0"/>
      </geometry>
      <material name="Maroon">
        <color rgba="0.5 0.0 0.0 1.0"/>
      </material>
    </visual>
    <collision>
      <origin rpy="0 0 0" xyz="0 0 1.0"/>
      <geometry>
        <box size="0.2 7.5 2.0"/>
      </geometry>
    </collision>
    <inertial>
      <origin rpy="0 0 0" xyz="0 0 1.0"/>
      <mass value="2"/>
      <inertia ixx="6.0e-2" ixy="0" ixz="0" iyy="6.0e-4" iyz="0" izz="6.0e-2"/>
    </inertial>
  </link>
  <joint name="wall_2_joint" type="continuous">
    <origin rpy="0 0 1.57" xyz="-0.1 2.8 0.0"/>
    <parent link="base_box"/>
    <child link="wall_2"/>
  </joint>
  <link name="wb1_w1">
    <visual>
      <origin rpy="0 0 0" xyz="0 0 0.1"/>
      <geometry>
        <box size="0.1 0.2 0.2"/>
      </geometry>
      <material name="White">
        <color rgba="1.0 1.0 1.0 1.0"/>
      </material>
    </visual>
    <collision>
      <origin rpy="0 0 0" xyz="0 0 0.1"/>
      <geometry>
        <box size="0.1 0.2 0.2"/>
      </geometry>
    </collision>
    <inertial>
      <origin rpy="0 0 0" xyz="0 0 0.1"/>
      <mass value="0.180"/>
      <inertia ixx="6.0e-4" ixy="0" ixz="0" iyy="6.0e-4" iyz="0" izz="6.0e-4"/>
    </inertial>
  </link>
  <joint name="wb1_w1_joint" type="fixed">
    <origin rpy="0 0 0" xyz="3.2 0.0 1.0"/>
    <parent link="base_box"/>
    <child link="wb1_w1"/>
  </joint>
  <link name="wb1_w2">
    <visual>
      <origin rpy="0 0 0" xyz="0 0 0.1"/>
      <geometry>
        <box size="0.1 0.2 0.2"/>
      </geometry>
      <material name="White">
        <color rgba="1.0 1.0 1.0 1.0"/>
      </material>
    </visual>
    <collision>
      <origin rpy="0 0 0" xyz="0 0 0.1"/>
      <geometry>
        <box size="0.1 0.2 0.2"/>
      </geometry>
    </collision>
    <inertial>
      <origin rpy="0 0 0" xyz="0 0 0.1"/>
      <mass value="0.180"/>
      <inertia ixx="6.0e-4" ixy="0" ixz="0" iyy="6.0e-4" iyz="0" izz="6.0e-4"/>
    </inertial>
  </link>
  <joint name="wb1_w2_joint" type="fixed">
    <origin rpy="0 0 1.57" xyz="1.4 2.7 1.0"/>
    <parent link="base_box"/>
    <child link="wb1_w2"/>
  </joint>
  <link name="marker01_link">
    <inertial>
      <mass value="0.001"/>
      <origin xyz="0 0 0"/>
      <inertia ixx="3.7499999999999997e-06" ixy="0.0" ixz="0.0" iyy="1.8750008333333333e-06" iyz="0.0" izz="1.8750008333333333e-06"/>
    </inertial>
    <visual>
      <origin rpy="0 1.57 0" xyz="0 0 0.0"/>
      <geometry>
        <mesh filename="file:///home/huan/RSP_final_project/install/ign_gazebo/share/ign_gazebo/meshes/marker01.stl" scale="0.25 0.25 0.25"/>
      </geometry>
      <material name="Gray">
        <color rgba="0.0 0.0 0.0 1.0"/>
      </material>
    </visual>
    <collision>
      <origin rpy="0 0 0" xyz="0 0 0"/>
      <geometry>
        <box size="0.1 0.1 0.1"/>
      </geometry>
    </collision>
  </link>
  <joint name="marker01_joint" type="fixed">
    <origin rpy="0 0 0" xyz="-0.05 0.0 0.1"/>
    <parent link="wb1_w1"/>
    <child link="marker01_link"/>
  </joint>
  <link name="marker03_link">
    <inertial>
      <mass value="0.001"/>
      <origin xyz="0 0 0"/>
      <inertia ixx="3.7499999999999997e-06" ixy="0.0" ixz="0.0" iyy="1.8750008333333333e-06" iyz="0.0" izz="1.8750008333333333e-06"/>
    </inertial>
    <visual>
      <origin rpy="0 1.57 0" xyz="0 0 0.0"/>
      <geometry>
        <mesh filename="file:///home/huan/RSP_final_project/install/ign_gazebo/share/ign_gazebo/meshes/marker03.stl" scale="0.25 0.25 0.25"/>
      </geometry>
      <material name="Gray">
        <color rgba="0.0 0.0 0.0 1.0"/>
      </material>
    </visual>
    <collision>
      <origin rpy="0 0 0" xyz="0 0 0"/>
      <geometry>
        <box size="0.1 0.1 0.1"/>
      </geometry>
    </collision>
  </link>
  <joint name="marker03_joint" type="fixed">
    <origin rpy="0 0 0" xyz="-0.05 0 0.1"/>
    <parent link="wb1_w2"/>
    <child link="marker03_link"/>
  </joint>
  <link name="shelf_link">
    <inertial>
      <mass value="4"/>
      <origin xyz="0 0 0"/>
      <inertia ixx="3" ixy="0.0" ixz="0.0" iyy="2" iyz="0.0" izz="2"/>
    </inertial>
    <visual>
      <origin rpy="0 0 0" xyz="0 0 0.0"/>
      <geometry>
        <mesh filename="file:///home/huan/RSP_final_project/install/ign_gazebo/share/ign_gazebo/meshes/shelf_big_movai.dae" scale="0.2 0.3 0.3"/>
      </geometry>
    </visual>
    <collision>
      <origin rpy="0 0 0" xyz="0 0 0.9"/>
      <geometry>
        <box size="4.5 0.6 1.8"/>
      </geometry>
    </collision>
  </link>
  <joint name="shelf_joint" type="continuous">
    <origin rpy="0 0 0" xyz="-2.0 -2.0 0.0"/>
    <parent link="base_box"/>
    <child link="shelf_link"/>
  </joint>
</robot>
