<?xml version="1.0" ?>
<!-- =================================================================================== -->
<!-- |    This document was autogenerated by xacro from moving_box.urdf.xacro          | -->
<!-- |    EDITING THIS FILE BY HAND IS NOT RECOMMENDED                                 | -->
<!-- =================================================================================== -->
<robot name="Moving_box">
  <link name="world">
    <origin rpy="0 0 0" xyz="0 0 0"/>
  </link>
  <link name="box_3">
    <visual>
      <origin rpy="0 0 0" xyz="0 0 0.0825"/>
      <geometry>
        <box size="0.255 0.21 0.165"/>
      </geometry>
      <material name="Almond">
        <color rgba="0.7 0.5 0.3 1.0"/>
      </material>
    </visual>
    <collision>
      <origin rpy="0 0 0" xyz="0 0 0.0825"/>
      <geometry>
        <box size="0.255 0.21 0.165"/>
      </geometry>
    </collision>
    <inertial>
      <origin rpy="0 0 0" xyz="0 0 0.0825"/>
      <mass value="0.01"/>
      <inertia ixx="6.0e-4" ixy="0" ixz="0" iyy="6.0e-4" iyz="0" izz="6.0e-4"/>
    </inertial>
  </link>
  <joint name="box_3_joint" type="planar">
    <axis xyz="0 0 1"/>
    <origin rpy="0 0 1.57" xyz="-0.21 -0.1275 0"/>
    <parent link="world"/>
    <child link="box_3"/>
  </joint>
</robot>
